Workbook
Name Slicer_City: #N/A
Name Slicer_Doctor_Name: #N/A
Name Slicer_Hospital_Department: #N/A
Name Slicer_Insurance_Provider: #N/A

Sheet Rawdata
A1: Patient_ID | B1: Patient_Name | C1: Age | D1: Gender | E1: Phone_Number | F1: Email | G1: City | H1: Hospital_Department | I1: Doctor_Name | J1: Visit_Date | K1: Appointment_Time | L1: Diagnosis | M1: Treatment_Type | N1: Admission_Type | O1: Insurance_Provider | P1: Bill_Amount | Q1: Payment_Status | R1: Follow_Up_Date | S1: Feedback_Score | T1: Notes
A2: P1654 | B2: Vijay Sharma | D2: Female | E2: 9163119785 | F2: vijaysharma@gmail.com | G2: Pune | H2: Cardiology | I2: Dr Nair | J2: 14/1/2024 | K2: 11:32 | L2: Fever | M2: Injection | N2: Walkin | O2: None | P2: 27993 | Q2: paid | R2: 19/5/2024 | T2: follow up required
A3: P1714 | B3: Meena Singh | D3: male | E3: 6438989805 | F3: meenasingh@gmail.com | G3: Madurai | H3: Cardiology | I3: Dr Iyer | J3: 28/6/2024 | K3: 15:34 | L3: Diabetes | M3: Observation | N3: Emergency | O3: None | Q3: pending | R3: 28/6/2024
A4: P1046 | B4: Divya Nair | D4: Male | E4: 7632629719 | G4: Kochi | H4: Dermatology | I4: Dr Sharma | J4: 12/3/2024 | K4: 18:17 | L4: Diabetes | M4: Injection | N4: Walkin | O4: None | P4: 48284 | Q4: Pending | T4: follow up required
A5: P1701 | B5: Anjali Sharma | D5: female | E5: 7149938334 | F5: anjalisharma@gmail.com | G5: Mumbai | H5: Pediatrics | I5: Dr Reddy | J5: 2024-11-16 | K5: 18:29 | L5: Hypertension | M5: Therapy | N5: Walkin | O5: HDFC Ergo | Q5: pending | S5: 5 | T5: review later
A6: P1370 | B6: Rahul Reddy | C6: 66 | D6: Male | E6: 9698408854 | F6: rahulreddy@gmail.com | G6: Hyderabad | H6: Dermatology | I6: Dr Mehta | J6: 26/11/2024 | K6: 14:24 | L6: Asthma | M6: Injection | N6: Referral | O6: None | T6: urgent
A7: P1114 | B7: Priya Patel | C7: 21 | D7: male | E7: 8150000991 | F7: priyapatel@gmail.com | G7: Pune | H7: Cardiology | I7: Dr Sharma | K7: 11:9 | L7: Skin Allergy | M7: Surgery | N7: Emergency | O7: None | Q7: Paid | S7: 2
A8: P1246 | B8: Karthik Kumar | C8: 11 | E8: 9289233844 | F8: karthikkumar@gmail.com | G8: Hyderabad | H8: Dermatology | I8: Dr Singh | K8: 14:13 | L8: Fracture | M8: Therapy | N8: Online | O8: ICICI Lombard | Q8: paid | R8: 4/4/2024 | S8: 1 | T8: urgent
A9: P1021 | B9: Karthik Verma | D9: Male | E9: 6304912982 | F9: karthikverma@mail.com | G9: Chennai | H9: Orthopedics | I9: Dr Rao | J9: 2/6/2024 | K9: 12:42 | L9: Asthma | M9: Surgery | N9: Walkin | O9: None | Q9: Pending | S9: 2
A10: P1099 | B10: Divya Patel | C10: 47 | D10: female | E10: 9710150572 | F10: divyapatel@mail.com | G10: Chennai | H10: Dermatology | I10: Dr Reddy | K10: 13:51 | L10: Diabetes | M10: Surgery | N10: Walkin | O10: HDFC Ergo | Q10: Pending | S10: 4 | T10: follow up required
A11: P1895 | B11: Vijay Das | C11: 71 | E11: 9590711152 | F11: vijaydas@gmail.com | G11: Bangalore | H11: Oncology | I11: Dr Sharma | J11: 2024-7-16 | K11: 11:55 | L11: Covid | M11: Medication | N11: Walkin | O11: Apollo Munich | Q11: Rejected | S11: 4 | T11: review later
A12: P1158 | B12: Rahul Iyer | C12: 28 | D12: male | E12: 6245522987 | F12: rahuliyer@gmail.com | G12: Vizag | H12: General Medicine | I12: Dr Nair | K12: 9:54 | L12: Hypertension | M12: Medication | N12: Emergency | O12: HDFC Ergo | P12: 26961 | Q12: pending | R12: 8/10/2024 | S12: 5
A13: P1429 | B13: Divya Gupta | D13: male | E13: 6877286584 | F13: divyagupta@mail.com | G13: Coimbatore | H13: Orthopedics | I13: Dr Iyer | J13: 2024-11-21 | K13: 15:20 | L13: Diabetes | M13: Medication | N13: Online | O13: None | P13: 37396 | Q13: Paid | S13: 2 | T13: urgent
A14: P1902 | B14: Vijay Nair | D14: female | E14: 9580907314 | F14: vijaynair@mail.com | G14: Delhi | H14: Pediatrics | I14: Dr Sharma | K14: 12:59 | L14: Diabetes | M14: Surgery | N14: Referral | O14: Star Health | Q14: pending | S14: 5 | T14: follow up required
A15: P1734 | B15: Anjali Nair | E15: 8098228320 | G15: Chennai | H15: Cardiology | I15: Dr Reddy | J15: 2024-1-1 | K15: 10:40 | L15: Migraine | M15: Surgery | N15: Online | O15: None | Q15: pending | R15: 1/2/2024 | T15: follow up required
A16: P1558 | B16: Arun Singh | D16: female | E16: 6547374338 | F16: arunsingh@gmail.com | G16: Delhi | H16: Neurology | I16: Dr Sharma | K16: 11:42 | L16: Diabetes | M16: Therapy | N16: Online | O16: None | P16: 49617 | Q16: Pending | R16: 28/3/2024 | S16: 4
A17: P1183 | B17: Sneha Singh | D17: Female | E17: 9381747775 | F17: snehasingh@mail.com | G17: Bangalore | H17: General Medicine | I17: Dr Sharma | J17: 2024-4-7 | K17: 13:19 | L17: Fracture | M17: Surgery | N17: Emergency | O17: HDFC Ergo | Q17: Rejected | S17: 3 | T17: review later
A18: P1695 | B18: Deepa Verma | C18: 43 | D18: male | E18: 6766942939 | F18: deepaverma@mail.com | G18: Delhi | H18: Cardiology | I18: Dr Rao | J18: 2024-6-24 | K18: 14:38 | L18: Diabetes | M18: Observation | N18: Walkin | O18: ICICI Lombard | Q18: paid | R18: 1/9/2024 | S18: 3 | T18: review later
A19: P1071 | B19: Divya Singh | C19: 80 | D19: male | E19: 8178074590 | G19: Madurai | H19: Neurology | I19: Dr Singh | J19: 23/5/2024 | K19: 14:42 | L19: Covid | M19: Surgery | N19: Referral | O19: Apollo Munich | P19: 36409 | Q19: Rejected | T19: urgent
A20: P1476 | B20: Ravi Das | C20: 33 | D20: Female | E20: 8829742424 | F20: ravidas@gmail.com | G20: Delhi | H20: Pediatrics | I20: Dr Reddy | J20: 21/10/2024 | K20: 18:19 | L20: Fracture | M20: Surgery | N20: Walkin | O20: Star Health | P20: 3528 | Q20: paid | S20: 4 | T20: follow up required
A21: P1735 | B21: Sneha Patel | D21: Female | E21: 8817747689 | F21: snehapatel@mail.com | G21: Chennai | H21: Oncology | I21: Dr Sharma | J21: 25/2/2024 | K21: 16:29 | L21: Fever | M21: Injection | N21: Walkin | O21: Star Health | P21: 30414 | Q21: paid | T21: review later
A22: P1627 | B22: Deepa Verma | C22: 55 | D22: Female | E22: 9193975799 | G22: Kochi | H22: Neurology | I22: Dr Sharma | K22: 15:40 | L22: Fracture | M22: Therapy | N22: Online | O22: Star Health | Q22: Pending | S22: 5
A23: P1141 | B23: Kumar Nair | D23: Male | E23: 7781844052 | G23: Coimbatore | H23: Pediatrics | I23: Dr Singh | J23: 2024-4-27 | K23: 14:57 | L23: Fever | M23: Injection | N23: Online | O23: Apollo Munich | Q23: Rejected | S23: 5 | T23: follow up required
A24: P1499 | B24: Rahul Iyer | C24: 56 | D24: female | E24: 7443665390 | F24: rahuliyer@mail.com | G24: Madurai | H24: Dermatology | I24: Dr Mehta | K24: 8:58 | L24: Covid | M24: Injection | N24: Emergency | O24: Star Health | Q24: Pending | R24: 28/8/2024 | S24: 1 | T24: urgent
A25: P1388 | B25: Anjali Nair | D25: female | E25: 7195103064 | G25: Delhi | H25: Oncology | I25: Dr Rao | J25: 16/1/2024 | K25: 13:14 | L25: Diabetes | M25: Medication | N25: Emergency | O25: HDFC Ergo | P25: 13565 | Q25: pending | R25: 5/4/2024 | S25: 4
A26: P1577 | B26: Rahul Das | D26: Female | E26: 8602289301 | F26: rahuldas@mail.com | G26: Bangalore | H26: Oncology | I26: Dr Sharma | J26: 6/5/2024 | K26: 12:36 | L26: Covid | M26: Observation | N26: Walkin | O26: Star Health
A27: P1815 | B27: Karthik Sharma | C27: 54 | D27: male | E27: 6296166921 | F27: karthiksharma@mail.com | G27: Coimbatore | H27: Cardiology | I27: Dr Sharma | J27: 2024-2-14 | K27: 18:57 | L27: Asthma | M27: Surgery | N27: Online | O27: HDFC Ergo | S27: 4 | T27: review later
A28: P1845 | B28: Sneha Gupta | D28: Male | E28: 7197987692 | G28: Mumbai | H28: Oncology | I28: Dr Singh | J28: 2024-11-13 | K28: 8:31 | L28: Skin Allergy | M28: Surgery | N28: Online | O28: HDFC Ergo | Q28: Rejected | S28: 5
A29: P1529 | B29: Rahul Kumar | C29: 46 | E29: 9256292393 | F29: rahulkumar@gmail.com | G29: Kochi | H29: Dermatology | I29: Dr Reddy | J29: 2024-1-3 | K29: 11:25 | L29: Fracture | M29: Therapy | N29: Referral | O29: Apollo Munich | Q29: Rejected | S29: 3 | T29: review later
A30: P1277 | B30: Priya Iyer | D30: male | E30: 6513483708 | F30: priyaiyer@mail.com | G30: Pune | H30: Oncology | I30: Dr Reddy | J30: 2024-4-24 | K30: 12:46 | L30: Migraine | M30: Medication | N30: Walkin | O30: ICICI Lombard | Q30: Pending | R30: 10/1/2024 | S30: 3
A31: P1997 | B31: Arun Verma | C31: 28 | D31: Male | E31: 9748302739 | F31: arunverma@gmail.com | G31: Vizag | H31: Neurology | I31: Dr Singh | J31: 16/8/2024 | K31: 12:55 | L31: Asthma | M31: Medication | N31: Emergency | O31: Apollo Munich | P31: 32727 | Q31: pending | R31: 21/11/2024 | S31: 2 | T31: follow up required
A32: P1830 | B32: Karthik Iyer | C32: 11 | E32: 9283259600 | G32: Vizag | H32: Pediatrics | I32: Dr Sharma | J32: 2024-9-13 | K32: 15:19 | L32: Covid | M32: Therapy | N32: Emergency | O32: None | P32: 49002 | Q32: Pending
A33: P1160 | B33: Rahul Reddy | D33: Male | E33: 7754569613 | G33: Vizag | H33: General Medicine | I33: Dr Iyer | J33: 2024-5-23 | K33: 15:4 | L33: Fracture | M33: Therapy | N33: Walkin | O33: Apollo Munich | Q33: Pending | T33: follow up required
A34: P1073 | B34: Arun Reddy | D34: female | E34: 6534094883 | G34: Delhi | H34: Dermatology | I34: Dr Singh | J34: 2024-9-16 | K34: 9:38 | L34: Fever | M34: Observation | N34: Referral | O34: None | P34: 16908 | Q34: Paid | R34: 8/11/2024 | T34: urgent
A35: P1590 | B35: Arun Reddy | C35: 53 | D35: male | E35: 6779489931 | F35: arunreddy@mail.com | G35: Madurai | H35: Dermatology | I35: Dr Sharma | J35: 2024-8-12 | K35: 13:20 | L35: Diabetes | M35: Surgery | N35: Referral | O35: Apollo Munich | Q35: Rejected | R35: 22/7/2024 | S35: 4
A36: P1322 | B36: Priya Singh | C36: 15 | E36: 7984173309 | G36: Chennai | H36: Orthopedics | I36: Dr Nair | J36: 2024-8-21 | K36: 8:13 | L36: Migraine | M36: Injection | N36: Walkin | O36: ICICI Lombard | Q36: paid | R36: 4/1/2024 | T36: follow up required
A37: P1318 | B37: Suresh Sharma | C37: 71 | D37: Female | E37: 9613809882 | F37: sureshsharma@gmail.com | G37: Kochi | H37: Cardiology | I37: Dr Reddy | J37: 2024-8-23 | K37: 16:45 | L37: Migraine | M37: Observation | N37: Online | O37: Apollo Munich | Q37: pending | R37: 5/7/2024 | S37: 5 | T37: follow up required
A38: P1884 | B38: Vijay Iyer | D38: Male | E38: 7214784185 | F38: vijayiyer@mail.com | G38: Delhi | H38: Oncology | I38: Dr Nair | J38: 19/11/2024 | K38: 15:34 | L38: Asthma | M38: Therapy | N38: Referral | O38: None | Q38: paid | R38: 11/4/2024 | S38: 5 | T38: review later
A39: P1239 | B39: Deepa Patel | C39: 40 | D39: female | E39: 7658195603 | F39: deepapatel@mail.com | G39: Hyderabad | H39: General Medicine | I39: Dr Rao | J39: 5/9/2024 | K39: 15:6 | L39: Asthma | M39: Medication | N39: Walkin | O39: Apollo Munich | P39: 43411 | Q39: Paid | S39: 5 | T39: review later
A40: P1665 | B40: Vijay Singh | C40: 54 | D40: male | E40: 8692081959 | F40: vijaysingh@mail.com | G40: Kochi | H40: Oncology | I40: Dr Nair | K40: 18:58 | L40: Migraine | M40: Surgery | N40: Emergency | O40: Apollo Munich | S40: 2 | T40: urgent
...

Sheet Pivot_Tables
A3: Row Labels | B3: Sum of Bill_Amount | D3: Row Labels | E3: Count of Patient_ID | G3: Row Labels | H3: Average of Feedback_Score | J3: Row Labels | K3: Sum of Bill_Amount | M3: Row Labels | N3: Count of Patient_Name
A4: Cardiology | B4: 6821176 | D4: Vizag | E4: 577 | G4: Dr Singh | H4: 3.0913621 | J4: Apollo Munich | K4: 9583678 | M4: Emergency | N4: 1364
A5: Dermatology | B5: 6336303 | D5: Pune | E5: 563 | G5: Dr Sharma | H5: 2.9942748 | J5: Hdfc Ergo | K5: 8754991 | M5: Online | N5: 1444
A6: General Medicine | B6: 6196583 | D6: Mumbai | E6: 562 | G6: Dr Reddy | H6: 3.0836364 | J6: Icici Lombard | K6: 8291979 | M6: Referral | N6: 1330
A7: Neurology | B7: 6222484 | D7: Madurai | E7: 533 | G7: Dr Rao | H7: 2.9359191 | J7: None | K7: 10226979 | M7: Walkin | N7: 1362
A8: Oncology | B8: 6348797 | D8: Kochi | E8: 531 | G8: Dr Nair | H8: 3.0961887 | J8: Star Health | K8: 8786523 | M8: Grand Total | N8: 5500
A9: Orthopedics | B9: 7251578 | D9: Hyderabad | E9: 515 | G9: Dr Mehta | H9: 3.0291262 | J9: Grand Total | K9: 45644150
A10: Pediatrics | B10: 6467229 | D10: Delhi | E10: 562 | G10: Dr Iyer | H10: 3.0678571
A11: Grand Total | B11: 45644150 | D11: Coimbatore | E11: 551 | G11: Grand Total | H11: 3.0426187
D12: Chennai | E12: 571
D13: Bangalore | E13: 535
D14: Grand Total | E14: 5500

Sheet Dashboard

Sheet Cleaned_Data
A1: Patient_ID | B1: Patient_Name | C1: Age | D1: Gender | E1: Phone_Number | F1: Email | G1: City | H1: Hospital_Department | I1: Doctor_Name | J1: Visit_Date | K1: Appointment_Time | L1: Diagnosis | M1: Treatment_Type | N1: Admission_Type | O1: Insurance_Provider | P1: Bill_Amount | Q1: Payment_Status | R1: Follow_Up_Date | S1: Feedback_Score | T1: Notes | U1: Bill_Amount_Labeling | V1: Age_Category | W1: Follow_Up_Status | X1: Bill_Amount_Category
A2: P1000 | B2: Sneha Reddy | C2: 37 | D2: Female | E2: +91 98748 98122 | F2: snehareddy@gmail.com | G2: Vizag | H2: Neurology | I2: Dr Nair | J2: 2024-06-09 | K2: 09:21 AM | L2: Fracture | M2: Surgery | N2: Online | O2: Star Health | P2: 0 | Q2: Paid | R2: 2024-03-12 | S2: 2 | T2: Review Later | U2: =IF(Cleaned_Data!P2>20000,"High-Bill","Normal-Bill") -> Normal-Bill | V2: =IF(C2>=60,"Senior-Citizen","Not-Senior-Citizen") -> Not-Senior-Citizen | W2: =IF(R2="N/A","Not-Required","Follow-Up-required") -> Follow-Up-required | X2: {=_xlfn.IFS(P2<5000,"Low",P2<=20000,"Medium",P2>20000,"High")} -> Low
A3: P1001 | B3: Sneha Iyer | C3: 42 | D3: Female | E3: +91 71720 84683 | F3: snehaiyer@gmail.com | G3: Hyderabad | H3: General Medicine | I3: Dr Sharma | J3: Not-Provided | K3: 05:25 PM | L3: Covid | M3: Therapy | N3: Walkin | O3: None | P3: 0 | Q3: Pending | R3: N/A | S3: 1 | T3: Review Later | U3: =IF(Cleaned_Data!P3>20000,"High-Bill","Normal-Bill") -> Normal-Bill | V3: =IF(C3>=60,"Senior-Citizen","Not-Senior-Citizen") -> Not-Senior-Citizen | W3: =IF(R3="N/A","Not-Required","Follow-Up-required") -> Not-Required | X3: {=_xlfn.IFS(P3<5000,"Low",P3<=20000,"Medium",P3>20000,"High")} -> Low
A4: P1001 | B4: Deepa Menon | C4: 27 | D4: Male | E4: +91 85816 77542 | F4: Not-Provided | G4: Chennai | H4: Cardiology | I4: Dr Sharma | J4: Not-Provided | K4: 08:53 AM | L4: Migraine | M4: Observation | N4: Referral | O4: None | P4: 42570 | Q4: Rejected | R4: N/A | S4: 5 | T4: Follow Up Required | U4: =IF(Cleaned_Data!P4>20000,"High-Bill","Normal-Bill") -> High-Bill | V4: =IF(C4>=60,"Senior-Citizen","Not-Senior-Citizen") -> Not-Senior-Citizen | W4: =IF(R4="N/A","Not-Required","Follow-Up-required") -> Not-Required | X4: {=_xlfn.IFS(P4<5000,"Low",P4<=20000,"Medium",P4>20000,"High")} -> High
A5: P1001 | B5: Divya Nair | C5: Invalid | D5: Missing | E5: +91 70110 05854 | F5: divyanair@mail.com | G5: Vizag | H5: Neurology | I5: Dr Mehta | J5: 2024-09-11 | K5: 05:27 PM | L5: Fracture | M5: Medication | N5: Emergency | O5: Star Health | P5: 0 | Q5: N/A | R5: 2024-07-21 | S5: 2 | T5: N/A | U5: =IF(Cleaned_Data!P5>20000,"High-Bill","Normal-Bill") -> Normal-Bill | V5: =IF(C5>=60,"Senior-Citizen","Not-Senior-Citizen") -> Senior-Citizen | W5: =IF(R5="N/A","Not-Required","Follow-Up-required") -> Follow-Up-required | X5: {=_xlfn.IFS(P5<5000,"Low",P5<=20000,"Medium",P5>20000,"High")} -> Low
A6: P1001 | B6: Vijay Reddy | C6: 65 | D6: Male | E6: +91 72482 34265 | F6: vijayreddy@gmail.com | G6: Delhi | H6: Cardiology | I6: Dr Nair | J6: 2024-03-22 | K6: 04:33 PM | L6: Fever | M6: Observation | N6: Online | O6: Apollo Munich | P6: 10515 | Q6: Rejected | R6: 2024-04-07 | S6: 4 | T6: Urgent | U6: =IF(Cleaned_Data!P6>20000,"High-Bill","Normal-Bill") -> Normal-Bill | V6: =IF(C6>=60,"Senior-Citizen","Not-Senior-Citizen") -> Senior-Citizen | W6: =IF(R6="N/A","Not-Required","Follow-Up-required") -> Follow-Up-required | X6: {=_xlfn.IFS(P6<5000,"Low",P6<=20000,"Medium",P6>20000,"High")} -> Medium
A7: P1001 | B7: Anjali Menon | C7: 24 | D7: Female | E7: +91 89234 00904 | F7: Not-Provided | G7: Mumbai | H7: Oncology | I7: Dr Mehta | J7: Not-Provided | K7: 11:08 AM | L7: Diabetes | M7: Injection | N7: Emergency | O7: Icici Lombard | P7: 0 | Q7: N/A | R7: N/A | S7: 5 | T7: N/A | U7: =IF(Cleaned_Data!P7>20000,"High-Bill","Normal-Bill") -> Normal-Bill | V7: =IF(C7>=60,"Senior-Citizen","Not-Senior-Citizen") -> Not-Senior-Citizen | W7: =IF(R7="N/A","Not-Required","Follow-Up-required") -> Not-Required | X7: {=_xlfn.IFS(P7<5000,"Low",P7<=20000,"Medium",P7>20000,"High")} -> Low
A8: P1001 | B8: Priya Iyer | C8: Invalid | D8: Male | E8: +91 86541 51449 | F8: priyaiyer@mail.com | G8: Madurai | H8: Dermatology | I8: Dr Singh | J8: 2024-04-27 | K8: 04:31 PM | L8: Migraine | M8: Observation | N8: Emergency | O8: None | P8: 13249 | Q8: Pending | R8: N/A | S8: N/A | T8: Follow Up Required | U8: =IF(Cleaned_Data!P8>20000,"High-Bill","Normal-Bill") -> Normal-Bill | V8: =IF(C8>=60,"Senior-Citizen","Not-Senior-Citizen") -> Senior-Citizen | W8: =IF(R8="N/A","Not-Required","Follow-Up-required") -> Not-Required | X8: {=_xlfn.IFS(P8<5000,"Low",P8<=20000,"Medium",P8>20000,"High")} -> Medium
A9: P1001 | B9: Ravi Nair | C9: 72 | D9: Missing | E9: +91 91362 13775 | F9: Not-Provided | G9: Bangalore | H9: Orthopedics | I9: Dr Reddy | J9: 2024-08-27 | K9: 03:44 PM | L9: Diabetes | M9: Therapy | N9: Online | O9: None | P9: 0 | Q9: Paid | R9: 2024-08-01 | S9: 5 | T9: Urgent | U9: =IF(Cleaned_Data!P9>20000,"High-Bill","Normal-Bill") -> Normal-Bill | V9: =IF(C9>=60,"Senior-Citizen","Not-Senior-Citizen") -> Senior-Citizen | W9: =IF(R9="N/A","Not-Required","Follow-Up-required") -> Follow-Up-required | X9: {=_xlfn.IFS(P9<5000,"Low",P9<=20000,"Medium",P9>20000,"High")} -> Low
A10: P1002 | B10: Arun Iyer | C10: Invalid | D10: Male | E10: +91 90787 37740 | F10: Not-Provided | G10: Coimbatore | H10: Neurology | I10: Dr Rao | J10: 2024-05-18 | K10: 05:59 PM | L10: Hypertension | M10: Surgery | N10: Emergency | O10: None | P10: 0 | Q10: Pending | R10: N/A | S10: N/A | T10: Follow Up Required | U10: =IF(Cleaned_Data!P10>20000,"High-Bill","Normal-Bill") -> Normal-Bill | V10: =IF(C10>=60,"Senior-Citizen","Not-Senior-Citizen") -> Senior-Citizen | W10: =IF(R10="N/A","Not-Required","Follow-Up-required") -> Not-Required | X10: {=_xlfn.IFS(P10<5000,"Low",P10<=20000,"Medium",P10>20000,"High")} -> Low
A11: P1002 | B11: Arun Menon | C11: Invalid | D11: Female | E11: +91 64271 34562 | F11: Not-Provided | G11: Hyderabad | H11: Orthopedics | I11: Dr Sharma | J11: Not-Provided | K11: 12:44 PM | L11: Asthma | M11: Medication | N11: Referral | O11: Icici Lombard | P11: 0 | Q11: Paid | R11: 2024-08-24 | S11: 2 | T11: N/A | U11: =IF(Cleaned_Data!P11>20000,"High-Bill","Normal-Bill") -> Normal-Bill | V11: =IF(C11>=60,"Senior-Citizen","Not-Senior-Citizen") -> Senior-Citizen | W11: =IF(R11="N/A","Not-Required","Follow-Up-required") -> Follow-Up-required | X11: {=_xlfn.IFS(P11<5000,"Low",P11<=20000,"Medium",P11>20000,"High")} -> Low
A12: P1002 | B12: Ravi Verma | C12: 21 | D12: Male | E12: +91 63529 86513 | F12: raviverma@mail.com | G12: Vizag | H12: Dermatology | I12: Dr Nair | J12: 2024-09-03 | K12: 03:23 PM | L12: Skin Allergy | M12: Medication | N12: Walkin | O12: None | P12: 0 | Q12: Rejected | R12: N/A | S12: 5 | T12: Follow Up Required | U12: =IF(Cleaned_Data!P12>20000,"High-Bill","Normal-Bill") -> Normal-Bill | V12: =IF(C12>=60,"Senior-Citizen","Not-Senior-Citizen") -> Not-Senior-Citizen | W12: =IF(R12="N/A","Not-Required","Follow-Up-required") -> Not-Required | X12: {=_xlfn.IFS(P12<5000,"Low",P12<=20000,"Medium",P12>20000,"High")} -> Low
A13: P1002 | B13: Vijay Iyer | C13: Invalid | D13: Male | E13: +91 74740 74305 | F13: vijayiyer@mail.com | G13: Pune | H13: Neurology | I13: Dr Nair | J13: 2024-05-15 | K13: 11:39 AM | L13: Fracture | M13: Observation | N13: Emergency | O13: Star Health | P13: 0 | Q13: Pending | R13: 2024-04-04 | S13: 3 | T13: Follow Up Required | U13: =IF(Cleaned_Data!P13>20000,"High-Bill","Normal-Bill") -> Normal-Bill | V13: =IF(C13>=60,"Senior-Citizen","Not-Senior-Citizen") -> Senior-Citizen | W13: =IF(R13="N/A","Not-Required","Follow-Up-required") -> Follow-Up-required | X13: {=_xlfn.IFS(P13<5000,"Low",P13<=20000,"Medium",P13>20000,"High")} -> Low
A14: P1002 | B14: Karthik Menon | C14: 35 | D14: Male | E14: +91 62367 75987 | F14: karthikmenon@mail.com | G14: Kochi | H14: Pediatrics | I14: Dr Nair | J14: 2024-05-24 | K14: 01:49 PM | L14: Fever | M14: Observation | N14: Emergency | O14: Apollo Munich | P14: 30196 | Q14: Pending | R14: 2024-03-17 | S14: 4 | T14: Urgent | U14: =IF(Cleaned_Data!P14>20000,"High-Bill","Normal-Bill") -> High-Bill | V14: =IF(C14>=60,"Senior-Citizen","Not-Senior-Citizen") -> Not-Senior-Citizen | W14: =IF(R14="N/A","Not-Required","Follow-Up-required") -> Follow-Up-required | X14: {=_xlfn.IFS(P14<5000,"Low",P14<=20000,"Medium",P14>20000,"High")} -> High
A15: P1002 | B15: Rahul Patel | C15: Invalid | D15: Male | E15: +91 72126 42412 | F15: Not-Provided | G15: Delhi | H15: General Medicine | I15: Dr Nair | J15: Not-Provided | K15: 03:00 PM | L15: Hypertension | M15: Observation | N15: Emergency | O15: Hdfc Ergo | P15: 43882 | Q15: Paid | R15: N/A | S15: 5 | T15: Urgent | U15: =IF(Cleaned_Data!P15>20000,"High-Bill","Normal-Bill") -> High-Bill | V15: =IF(C15>=60,"Senior-Citizen","Not-Senior-Citizen") -> Senior-Citizen | W15: =IF(R15="N/A","Not-Required","Follow-Up-required") -> Not-Required | X15: {=_xlfn.IFS(P15<5000,"Low",P15<=20000,"Medium",P15>20000,"High")} -> High
A16: P1002 | B16: Rahul Sharma | C16: 41 | D16: Female | E16: +91 80726 02009 | F16: rahulsharma@gmail.com | G16: Madurai | H16: Cardiology | I16: Dr Mehta | J16: 2024-06-12 | K16: 09:37 AM | L16: Skin Allergy | M16: Medication | N16: Walkin | O16: Hdfc Ergo | P16: 0 | Q16: Pending | R16: N/A | S16: 1 | T16: N/A | U16: =IF(Cleaned_Data!P16>20000,"High-Bill","Normal-Bill") -> Normal-Bill | V16: =IF(C16>=60,"Senior-Citizen","Not-Senior-Citizen") -> Not-Senior-Citizen | W16: =IF(R16="N/A","Not-Required","Follow-Up-required") -> Not-Required | X16: {=_xlfn.IFS(P16<5000,"Low",P16<=20000,"Medium",P16>20000,"High")} -> Low
A17: P1002 | B17: Suresh Singh | C17: Invalid | D17: Female | E17: +91 85797 66451 | F17: sureshsingh@gmail.com | G17: Delhi | H17: General Medicine | I17: Dr Iyer | J17: 2024-11-22 | K17: 10:59 AM | L17: Hypertension | M17: Medication | N17: Online | O17: Icici Lombard | P17: 13397 | Q17: Paid | R17: N/A | S17: 4 | T17: Urgent | U17: =IF(Cleaned_Data!P17>20000,"High-Bill","Normal-Bill") -> Normal-Bill | V17: =IF(C17>=60,"Senior-Citizen","Not-Senior-Citizen") -> Senior-Citizen | W17: =IF(R17="N/A","Not-Required","Follow-Up-required") -> Not-Required | X17: {=_xlfn.IFS(P17<5000,"Low",P17<=20000,"Medium",P17>20000,"High")} -> Medium
A18: P1003 | B18: Deepa Sharma | C18: Invalid | D18: Female | E18: +91 92418 24322 | F18: deepasharma@gmail.com | G18: Chennai | H18: Orthopedics | I18: Dr Singh | J18: 2024-07-06 | K18: 11:08 AM | L18: Covid | M18: Therapy | N18: Referral | O18: Hdfc Ergo | P18: 0 | Q18: Pending | R18: 2024-01-08 | S18: 4 | T18: Urgent | U18: =IF(Cleaned_Data!P18>20000,"High-Bill","Normal-Bill") -> Normal-Bill | V18: =IF(C18>=60,"Senior-Citizen","Not-Senior-Citizen") -> Senior-Citizen | W18: =IF(R18="N/A","Not-Required","Follow-Up-required") -> Follow-Up-required | X18: {=_xlfn.IFS(P18<5000,"Low",P18<=20000,"Medium",P18>20000,"High")} -> Low
A19: P1003 | B19: Anjali Sharma | C19: 32 | D19: Female | E19: +91 80649 00406 | F19: anjalisharma@mail.com | G19: Bangalore | H19: Orthopedics | I19: Dr Nair | J19: Not-Provided | K19: 06:14 PM | L19: Skin Allergy | M19: Injection | N19: Walkin | O19: Star Health | P19: 36948 | Q19: Pending | R19: 2024-08-26 | S19: 3 | T19: Review Later | U19: =IF(Cleaned_Data!P19>20000,"High-Bill","Normal-Bill") -> High-Bill | V19: =IF(C19>=60,"Senior-Citizen","Not-Senior-Citizen") -> Not-Senior-Citizen | W19: =IF(R19="N/A","Not-Required","Follow-Up-required") -> Follow-Up-required | X19: {=_xlfn.IFS(P19<5000,"Low",P19<=20000,"Medium",P19>20000,"High")} -> High
A20: P1003 | B20: Divya Verma | C20: Invalid | D20: Male | E20: +91 70930 35801 | F20: Not-Provided | G20: Pune | H20: Orthopedics | I20: Dr Sharma | J20: 2024-12-19 | K20: 10:05 AM | L20: Hypertension | M20: Therapy | N20: Online | O20: None | P20: 0 | Q20: Paid | R20: 2024-02-20 | S20: 2 | T20: Urgent | U20: =IF(Cleaned_Data!P20>20000,"High-Bill","Normal-Bill") -> Normal-Bill | V20: =IF(C20>=60,"Senior-Citizen","Not-Senior-Citizen") -> Senior-Citizen | W20: =IF(R20="N/A","Not-Required","Follow-Up-required") -> Follow-Up-required | X20: {=_xlfn.IFS(P20<5000,"Low",P20<=20000,"Medium",P20>20000,"High")} -> Low
A21: P1003 | B21: Ravi Kumar | C21: 69 | D21: Female | E21: +91 86505 96504 | F21: Not-Provided | G21: Delhi | H21: Oncology | I21: Dr Rao | J21: Not-Provided | K21: 03:42 PM | L21: Diabetes | M21: Injection | N21: Online | O21: Star Health | P21: 47260 | Q21: Rejected | R21: N/A | S21: 3 | T21: N/A | U21: =IF(Cleaned_Data!P21>20000,"High-Bill","Normal-Bill") -> High-Bill | V21: =IF(C21>=60,"Senior-Citizen","Not-Senior-Citizen") -> Senior-Citizen | W21: =IF(R21="N/A","Not-Required","Follow-Up-required") -> Not-Required | X21: {=_xlfn.IFS(P21<5000,"Low",P21<=20000,"Medium",P21>20000,"High")} -> High
A22: P1003 | B22: Suresh Das | C22: 51 | D22: Missing | E22: +91 66608 32896 | F22: sureshdas@gmail.com | G22: Coimbatore | H22: General Medicine | I22: Dr Sharma | J22: 2024-09-18 | K22: 04:01 PM | L22: Hypertension | M22: Surgery | N22: Online | O22: Hdfc Ergo | P22: 0 | Q22: Paid | R22: 2024-11-09 | S22: N/A | T22: N/A | U22: =IF(Cleaned_Data!P22>20000,"High-Bill","Normal-Bill") -> Normal-Bill | V22: =IF(C22>=60,"Senior-Citizen","Not-Senior-Citizen") -> Not-Senior-Citizen | W22: =IF(R22="N/A","Not-Required","Follow-Up-required") -> Follow-Up-required | X22: {=_xlfn.IFS(P22<5000,"Low",P22<=20000,"Medium",P22>20000,"High")} -> Low
A23: P1003 | B23: Suresh Sharma | C23: 48 | D23: Male | E23: +91 75279 03576 | F23: sureshsharma@mail.com | G23: Vizag | H23: Neurology | I23: Dr Iyer | J23: 2024-09-05 | K23: 09:20 AM | L23: Fracture | M23: Surgery | N23: Walkin | O23: Icici Lombard | P23: 0 | Q23: Rejected | R23: 2024-08-19 | S23: 5 | T23: Review Later | U23: =IF(Cleaned_Data!P23>20000,"High-Bill","Normal-Bill") -> Normal-Bill | V23: =IF(C23>=60,"Senior-Citizen","Not-Senior-Citizen") -> Not-Senior-Citizen | W23: =IF(R23="N/A","Not-Required","Follow-Up-required") -> Follow-Up-required | X23: {=_xlfn.IFS(P23<5000,"Low",P23<=20000,"Medium",P23>20000,"High")} -> Low
A24: P1004 | B24: Suresh Nair | C24: 34 | D24: Female | E24: +91 77050 16899 | F24: sureshnair@gmail.com | G24: Madurai | H24: Cardiology | I24: Dr Rao | J24: Not-Provided | K24: 02:01 PM | L24: Migraine | M24: Injection | N24: Emergency | O24: Apollo Munich | P24: 38522 | Q24: Pending | R24: N/A | S24: N/A | T24: N/A | U24: =IF(Cleaned_Data!P24>20000,"High-Bill","Normal-Bill") -> High-Bill | V24: =IF(C24>=60,"Senior-Citizen","Not-Senior-Citizen") -> Not-Senior-Citizen | W24: =IF(R24="N/A","Not-Required","Follow-Up-required") -> Not-Required | X24: {=_xlfn.IFS(P24<5000,"Low",P24<=20000,"Medium",P24>20000,"High")} -> High
A25: P1004 | B25: Meena Gupta | C25: 45 | D25: Male | E25: +91 91437 50861 | F25: Not-Provided | G25: Pune | H25: Orthopedics | I25: Dr Sharma | J25: 2024-02-04 | K25: 10:12 AM | L25: Migraine | M25: Injection | N25: Walkin | O25: Hdfc Ergo | P25: 0 | Q25: Rejected | R25: 2024-06-21 | S25: N/A | T25: N/A | U25: =IF(Cleaned_Data!P25>20000,"High-Bill","Normal-Bill") -> Normal-Bill | V25: =IF(C25>=60,"Senior-Citizen","Not-Senior-Citizen") -> Not-Senior-Citizen | W25: =IF(R25="N/A","Not-Required","Follow-Up-required") -> Follow-Up-required | X25: {=_xlfn.IFS(P25<5000,"Low",P25<=20000,"Medium",P25>20000,"High")} -> Low
A26: P1004 | B26: Suresh Patel | C26: Invalid | D26: Female | E26: +91 91793 76709 | F26: Not-Provided | G26: Coimbatore | H26: Pediatrics | I26: Dr Iyer | J26: Not-Provided | K26: 03:45 PM | L26: Migraine | M26: Surgery | N26: Online | O26: Hdfc Ergo | P26: 33146 | Q26: Rejected | R26: N/A | S26: 2 | T26: Follow Up Required | U26: =IF(Cleaned_Data!P26>20000,"High-Bill","Normal-Bill") -> High-Bill | V26: =IF(C26>=60,"Senior-Citizen","Not-Senior-Citizen") -> Senior-Citizen | W26: =IF(R26="N/A","Not-Required","Follow-Up-required") -> Not-Required | X26: {=_xlfn.IFS(P26<5000,"Low",P26<=20000,"Medium",P26>20000,"High")} -> High
A27: P1005 | B27: Sneha Sharma | C27: 74 | D27: Missing | E27: +91 60308 98225 | F27: Not-Provided | G27: Mumbai | H27: Dermatology | I27: Dr Sharma | J27: 2024-07-11 | K27: 02:41 PM | L27: Migraine | M27: Therapy | N27: Online | O27: None | P27: 0 | Q27: Rejected | R27: 2024-07-22 | S27: 4 | T27: Review Later | U27: =IF(Cleaned_Data!P27>20000,"High-Bill","Normal-Bill") -> Normal-Bill | V27: =IF(C27>=60,"Senior-Citizen","Not-Senior-Citizen") -> Senior-Citizen | W27: =IF(R27="N/A","Not-Required","Follow-Up-required") -> Follow-Up-required | X27: {=_xlfn.IFS(P27<5000,"Low",P27<=20000,"Medium",P27>20000,"High")} -> Low
A28: P1005 | B28: Anjali Singh | C28: 43 | D28: Male | E28: +91 93942 45653 | F28: Not-Provided | G28: Coimbatore | H28: Oncology | I28: Dr Reddy | J28: 2024-12-07 | K28: 12:14 PM | L28: Migraine | M28: Injection | N28: Referral | O28: None | P28: 0 | Q28: Pending | R28: 2024-09-18 | S28: N/A | T28: Review Later | U28: =IF(Cleaned_Data!P28>20000,"High-Bill","Normal-Bill") -> Normal-Bill | V28: =IF(C28>=60,"Senior-Citizen","Not-Senior-Citizen") -> Not-Senior-Citizen | W28: =IF(R28="N/A","Not-Required","Follow-Up-required") -> Follow-Up-required | X28: {=_xlfn.IFS(P28<5000,"Low",P28<=20000,"Medium",P28>20000,"High")} -> Low
A29: P1005 | B29: Suresh Iyer | C29: Invalid | D29: Male | E29: +91 94843 27337 | F29: sureshiyer@mail.com | G29: Mumbai | H29: Oncology | I29: Dr Reddy | J29: 2024-05-07 | K29: 06:09 PM | L29: Diabetes | M29: Surgery | N29: Referral | O29: Apollo Munich | P29: 24084 | Q29: Paid | R29: 2024-06-15 | S29: N/A | T29: Follow Up Required | U29: =IF(Cleaned_Data!P29>20000,"High-Bill","Normal-Bill") -> High-Bill | V29: =IF(C29>=60,"Senior-Citizen","Not-Senior-Citizen") -> Senior-Citizen | W29: =IF(R29="N/A","Not-Required","Follow-Up-required") -> Follow-Up-required | X29: {=_xlfn.IFS(P29<5000,"Low",P29<=20000,"Medium",P29>20000,"High")} -> High
A30: P1006 | B30: Anjali Das | C30: Invalid | D30: Female | E30: +91 90088 70380 | F30: anjalidas@gmail.com | G30: Chennai | H30: Pediatrics | I30: Dr Sharma | J30: 2024-02-13 | K30: 11:28 AM | L30: Asthma | M30: Medication | N30: Walkin | O30: Star Health | P30: 30805 | Q30: N/A | R30: 2024-08-09 | S30: 1 | T30: Follow Up Required | U30: =IF(Cleaned_Data!P30>20000,"High-Bill","Normal-Bill") -> High-Bill | V30: =IF(C30>=60,"Senior-Citizen","Not-Senior-Citizen") -> Senior-Citizen | W30: =IF(R30="N/A","Not-Required","Follow-Up-required") -> Follow-Up-required | X30: {=_xlfn.IFS(P30<5000,"Low",P30<=20000,"Medium",P30>20000,"High")} -> High
A31: P1006 | B31: Arun Iyer | C31: Invalid | D31: Male | E31: +91 82623 43378 | F31: aruniyer@gmail.com | G31: Mumbai | H31: Neurology | I31: Dr Rao | J31: Not-Provided | K31: 04:43 PM | L31: Fracture | M31: Medication | N31: Emergency | O31: Icici Lombard | P31: 0 | Q31: Pending | R31: N/A | S31: 4 | T31: Review Later | U31: =IF(Cleaned_Data!P31>20000,"High-Bill","Normal-Bill") -> Normal-Bill | V31: =IF(C31>=60,"Senior-Citizen","Not-Senior-Citizen") -> Senior-Citizen | W31: =IF(R31="N/A","Not-Required","Follow-Up-required") -> Not-Required | X31: {=_xlfn.IFS(P31<5000,"Low",P31<=20000,"Medium",P31>20000,"High")} -> Low
A32: P1006 | B32: Deepa Singh | C32: Invalid | D32: Male | E32: +91 90874 65568 | F32: deepasingh@mail.com | G32: Kochi | H32: Pediatrics | I32: Dr Sharma | J32: 2024-11-01 | K32: 02:59 PM | L32: Covid | M32: Medication | N32: Walkin | O32: Apollo Munich | P32: 0 | Q32: Paid | R32: N/A | S32: 2 | T32: Urgent | U32: =IF(Cleaned_Data!P32>20000,"High-Bill","Normal-Bill") -> Normal-Bill | V32: =IF(C32>=60,"Senior-Citizen","Not-Senior-Citizen") -> Senior-Citizen | W32: =IF(R32="N/A","Not-Required","Follow-Up-required") -> Not-Required | X32: {=_xlfn.IFS(P32<5000,"Low",P32<=20000,"Medium",P32>20000,"High")} -> Low
A33: P1006 | B33: Suresh Nair | C33: 87 | D33: Male | E33: +91 63647 26064 | F33: Not-Provided | G33: Chennai | H33: Neurology | I33: Dr Singh | J33: 2024-05-13 | K33: 06:35 PM | L33: Diabetes | M33: Observation | N33: Emergency | O33: Apollo Munich | P33: 2213 | Q33: Pending | R33: 2024-02-14 | S33: 3 | T33: Urgent | U33: =IF(Cleaned_Data!P33>20000,"High-Bill","Normal-Bill") -> Normal-Bill | V33: =IF(C33>=60,"Senior-Citizen","Not-Senior-Citizen") -> Senior-Citizen | W33: =IF(R33="N/A","Not-Required","Follow-Up-required") -> Follow-Up-required | X33: {=_xlfn.IFS(P33<5000,"Low",P33<=20000,"Medium",P33>20000,"High")} -> Low
A34: P1007 | B34: Rahul Iyer | C34: Invalid | D34: Male | E34: +91 74092 74786 | F34: rahuliyer@gmail.com | G34: Chennai | H34: General Medicine | I34: Dr Reddy | J34: Not-Provided | K34: 11:32 AM | L34: Skin Allergy | M34: Medication | N34: Online | O34: Star Health | P34: 29088 | Q34: Paid | R34: N/A | S34: 5 | T34: Review Later | U34: =IF(Cleaned_Data!P34>20000,"High-Bill","Normal-Bill") -> High-Bill | V34: =IF(C34>=60,"Senior-Citizen","Not-Senior-Citizen") -> Senior-Citizen | W34: =IF(R34="N/A","Not-Required","Follow-Up-required") -> Not-Required | X34: {=_xlfn.IFS(P34<5000,"Low",P34<=20000,"Medium",P34>20000,"High")} -> High
A35: P1007 | B35: Vijay Patel | C35: Invalid | D35: Female | E35: +91 89394 06119 | F35: vijaypatel@mail.com | G35: Madurai | H35: Neurology | I35: Dr Iyer | J35: 2024-09-13 | K35: 01:48 PM | L35: Skin Allergy | M35: Observation | N35: Referral | O35: Star Health | P35: 0 | Q35: Paid | R35: 2024-05-14 | S35: 1 | T35: N/A | U35: =IF(Cleaned_Data!P35>20000,"High-Bill","Normal-Bill") -> Normal-Bill | V35: =IF(C35>=60,"Senior-Citizen","Not-Senior-Citizen") -> Senior-Citizen | W35: =IF(R35="N/A","Not-Required","Follow-Up-required") -> Follow-Up-required | X35: {=_xlfn.IFS(P35<5000,"Low",P35<=20000,"Medium",P35>20000,"High")} -> Low
A36: P1007 | B36: Sneha Sharma | C36: 89 | D36: Female | E36: +91 76158 44526 | F36: Not-Provided | G36: Mumbai | H36: Oncology | I36: Dr Sharma | J36: 2024-05-06 | K36: 12:13 PM | L36: Asthma | M36: Medication | N36: Referral | O36: Star Health | P36: 0 | Q36: N/A | R36: N/A | S36: 5 | T36: N/A | U36: =IF(Cleaned_Data!P36>20000,"High-Bill","Normal-Bill") -> Normal-Bill | V36: =IF(C36>=60,"Senior-Citizen","Not-Senior-Citizen") -> Senior-Citizen | W36: =IF(R36="N/A","Not-Required","Follow-Up-required") -> Not-Required | X36: {=_xlfn.IFS(P36<5000,"Low",P36<=20000,"Medium",P36>20000,"High")} -> Low
A37: P1007 | B37: Rahul Sharma | C37: 17 | D37: Female | E37: +91 63099 52300 | F37: Not-Provided | G37: Pune | H37: Cardiology | I37: Dr Singh | J37: Not-Provided | K37: 11:55 AM | L37: Hypertension | M37: Observation | N37: Referral | O37: None | P37: 0 | Q37: Paid | R37: N/A | S37: 5 | T37: Follow Up Required | U37: =IF(Cleaned_Data!P37>20000,"High-Bill","Normal-Bill") -> Normal-Bill | V37: =IF(C37>=60,"Senior-Citizen","Not-Senior-Citizen") -> Not-Senior-Citizen | W37: =IF(R37="N/A","Not-Required","Follow-Up-required") -> Not-Required | X37: {=_xlfn.IFS(P37<5000,"Low",P37<=20000,"Medium",P37>20000,"High")} -> Low
A38: P1007 | B38: Ravi Reddy | C38: Invalid | D38: Male | E38: +91 94947 47874 | F38: ravireddy@mail.com | G38: Hyderabad | H38: Neurology | I38: Dr Rao | J38: 2024-09-18 | K38: 05:27 PM | L38: Hypertension | M38: Therapy | N38: Walkin | O38: Hdfc Ergo | P38: 27206 | Q38: Paid | R38: 2024-01-22 | S38: N/A | T38: N/A | U38: =IF(Cleaned_Data!P38>20000,"High-Bill","Normal-Bill") -> High-Bill | V38: =IF(C38>=60,"Senior-Citizen","Not-Senior-Citizen") -> Senior-Citizen | W38: =IF(R38="N/A","Not-Required","Follow-Up-required") -> Follow-Up-required | X38: {=_xlfn.IFS(P38<5000,"Low",P38<=20000,"Medium",P38>20000,"High")} -> High
A39: P1007 | B39: Manoj Menon | C39: Invalid | D39: Male | E39: +91 75488 44313 | F39: manojmenon@gmail.com | G39: Bangalore | H39: Pediatrics | I39: Dr Iyer | J39: 2024-06-02 | K39: 04:59 PM | L39: Fracture | M39: Medication | N39: Emergency | O39: Hdfc Ergo | P39: 0 | Q39: Paid | R39: N/A | S39: N/A | T39: Review Later | U39: =IF(Cleaned_Data!P39>20000,"High-Bill","Normal-Bill") -> Normal-Bill | V39: =IF(C39>=60,"Senior-Citizen","Not-Senior-Citizen") -> Senior-Citizen | W39: =IF(R39="N/A","Not-Required","Follow-Up-required") -> Not-Required | X39: {=_xlfn.IFS(P39<5000,"Low",P39<=20000,"Medium",P39>20000,"High")} -> Low
A40: P1007 | B40: Anjali Verma | C40: 54 | D40: Female | E40: +91 67099 08562 | F40: Not-Provided | G40: Chennai | H40: Neurology | I40: Dr Singh | J40: 2024-02-13 | K40: 08:27 AM | L40: Diabetes | M40: Injection | N40: Referral | O40: None | P40: 0 | Q40: Paid | R40: 2024-10-17 | S40: N/A | T40: Follow Up Required | U40: =IF(Cleaned_Data!P40>20000,"High-Bill","Normal-Bill") -> Normal-Bill | V40: =IF(C40>=60,"Senior-Citizen","Not-Senior-Citizen") -> Not-Senior-Citizen | W40: =IF(R40="N/A","Not-Required","Follow-Up-required") -> Follow-Up-required | X40: {=_xlfn.IFS(P40<5000,"Low",P40<=20000,"Medium",P40>20000,"High")} -> Low
...

Sheet Data_Validation
B2: Data_Validation | C2: Getted_values
B3: Patient_Name | C3: Average_Bill_Amt
B4: Kumar Menon | C4: =AVERAGEIF(Cleaned_Data!B2:B5501,B4,Cleaned_Data!P2:P5501) -> 7541.6585
B6: Hospital_Department | C6: Total_Patients
B7: Cardiology | C7: =COUNTIF(Cleaned_Data!H2:H5501,B7) -> 785
B9: Patient_ID | C9: Insurance_Type
B10: P1009 | C10: =_xlfn.XLOOKUP($B$10,Cleaned_Data!$A$2:$A$5501,Cleaned_Data!$O$2:$O$5501) -> Icici Lombard
B12: Patient_ID | C12: Treatment_Category
B13: P1159 | C13: =_xlfn.XLOOKUP($B$13,Cleaned_Data!$A$2:$A$5501,Cleaned_Data!$M$2:$M$5501) -> Injection
B15: City | C15: Hospital_Zone
B16: Delhi | C16: =_xlfn.XLOOKUP($B$16,Cleaned_Data!$G$2:$G$5501,Cleaned_Data!$H$2:$H$5501) -> Cardiology

Sheet Aggregate_Functions
E3: Total_Patients
E4: =COUNTA(Cleaned_Data!B2:B5501) -> 5500
E6: Total_Revenue | G6: In Lakhs
E7: =SUM(Cleaned_Data!P2:P5501) -> 45644150 | G7: 45644150
E9: Max_Revenue | G9: In Thousands
E10: =MAX(Cleaned_Data!$P$2:$P$5501) -> 49959 | G10: =MAX(Cleaned_Data!$P$2:$P$5501) -> 49959
E12: Min_Revenue
E13: =MIN(Cleaned_Data!$P$2:$P$5501) -> 0
E15: Average_Revenue
E16: =AVERAGE(Cleaned_Data!$P$2:$P$5501) -> 8298.9364
E18: Average_Feedback_Score
E19: =AVERAGE(Cleaned_Data!$S$2:$S$5501) -> 3.0426187

Sheet Lookups
D2: Doctor Reference Table
D3: Doctor_Name | E3: Hospital_Department
D4: Dr Mehta | E4: =_xlfn.XLOOKUP(D4,Cleaned_Data!$I$2:$I$5501,Cleaned_Data!$H$2:$H$5501) -> Neurology
D7: City_Region_Table
D8: Patient_Name | E8: Region_Name
D9: Arun Kumar | E9: =_xlfn.XLOOKUP(D9,Cleaned_Data!$B$2:$B$5501,Cleaned_Data!$G$2:$G$5501) -> Hyderabad

Sheet Questions
A1: Questions:-
A2: 1. Identify and remove duplicate patient records based on Patient_ID.
A3: 2. Standardize the Gender column so values appear only as Male or Female.
A4: 3. Fill blank Email values with 'Not Provided'.
A5: 4. Identify rows where Age is missing or invalid.
A6: 5. Remove extra spaces from Patient_Name.
A7: 6. Convert Visit_Date values into a consistent date format.
A8: 7. Replace blank Bill_Amount values with 0.
A9: 8. Standardize Payment_Status values to Paid, Pending, or Rejected.
A10: 9. Calculate the total hospital revenue using Bill_Amount.
A11: 10. Calculate the average bill amount per patient.
A12: 11. Find the maximum bill amount in the dataset.
... A31: 30. Create a pivot table showing Patient Count by Admission Type.
